<?xml version="1.0" ?>
<!-- =================================================================================== -->
<!-- |    This document was autogenerated by xacro from /home/nastya/catkin_ws/src/digital_twin/description/urdf/for_assistant.xacro | -->
<!-- |    EDITING THIS FILE BY HAND IS NOT RECOMMENDED                                 | -->
<!-- =================================================================================== -->
<robot name="robot">
    <!-- добавление цветов -->
    <material name="grey">
        <color rgba="0.5 0.5 0.5 1" />
    </material>
    <material name="white">
        <color rgba="1 1 1 1" />
    </material>
    <material name="light_grey">
        <color rgba="0.8 0.8 0.8 1" />
    </material>
    <material name="black">
        <color rgba="0 0 0 1" />
    </material>
    <link name="world" />
    <!-- прикрепление неподвижного основания робота к миру-->
    <joint name="fixed" type="fixed">
        <parent link="world" />
        <child link="base1_link" />
    </joint>
    <!-- base1_link — неподвижное звено основания, находится дальше от link1 -->
    <link name="base1_link">
        <collision>
            <origin rpy="0 0 0" xyz="0 0 0.005" />
            <geometry>
                <cylinder length="0.01" radius="0.115" />
            </geometry>
        </collision>
        <visual>
            <origin rpy="0 0 0" xyz="0 0 0.005" />
            <geometry>
                <cylinder length="0.01" radius="0.115" />
            </geometry>
            <material name="light_grey" />
        </visual>
        
<inertial>
            <mass value="4" />
            <inertia ixx="1.0" ixy="0.0" ixz="0.0" iyy="1.0" iyz="0.0" izz="1.0" />
        </inertial>

    </link>
    <!-- base2_link — неподвижное звено основания, находится ближе к link1 -->
    <link name="base2_link">
        <collision>
            <geometry>
                <cylinder length="0.05" radius="0.0625" />
            </geometry>
        </collision>
        <visual>
            <geometry>
                <cylinder length="0.05" radius="0.0625" />
            </geometry>
            <material name="light_grey" />
        </visual>
        
<inertial>
            <mass value="2" />
            <inertia ixx="1.0" ixy="0.0" ixz="0.0" iyy="1.0" iyz="0.0" izz="1.0" />
        </inertial>

    </link>
    <!-- base1_to_base2 — фиксированное соединение -->
    <joint name="base1_to_base2" type="fixed">
        <parent link="base1_link" />
        <child link="base2_link" />
        <origin rpy="0 0 0" xyz="0 0 0.035" />
    </joint>
    <!-- link1 — звено, которое осуществляет поворот основания манипулятора влево/вправо -->
    <link name="link1">
        <collision>
            <geometry>
                <cylinder length="0.025" radius="0.02" />
            </geometry>
        </collision>
        <visual>
            <geometry>
                <cylinder length="0.025" radius="0.02" />
            </geometry>
            <material name="light_grey" />
        </visual>
        
<inertial>
            <mass value="1e-05" />
            <inertia ixx="1.0" ixy="0.0" ixz="0.0" iyy="1.0" iyz="0.0" izz="1.0" />
        </inertial>

    </link>
    <!-- base2_to_link1 — подвижное соединение -->
    <joint name="base2_to_link1" type="revolute">
        <parent link="base2_link" />
        <child link="link1" />
        <origin rpy="0 0 0" xyz="0 0 0.037500000000000006" />
        <axis xyz="0 0 1" />
        <limit effort="0.245166" lower="-1.57" upper="1.57" velocity="3.15" />
        <dynamics damping="0.0" friction="0.0" />
    </joint>
    <!-- imu_block1 — внешняя часть imu-датчика, которая находится рядом с link1 -->
    <link name="imu_block1">
        <collision>
            <origin rpy="0 0 0" xyz="0 0 0" />
            <geometry>
                <box size="0.015 0.025 0.005" />
            </geometry>
        </collision>
        <visual>
            <origin rpy="0 0 0" xyz="0 0 0" />
            <geometry>
                <box size="0.015 0.025 0.005" />
            </geometry>
            <material name="black" />
        </visual>
        
<inertial>
            <mass value="1e-05" />
            <inertia ixx="1.0" ixy="0.0" ixz="0.0" iyy="1.0" iyz="0.0" izz="1.0" />
        </inertial>

    </link>
    <!-- link1_to_imu_block1 — фиксированное соединение -->
    <joint name="link1_to_imu_block1" type="fixed">
        <parent link="link1" />
        <child link="imu_block1" />
        <origin rpy="0 0 0" xyz="0.0325 0 0.015000000000000001" />
    </joint>
    <!-- for_link2_1 — неподвижное звено, которое находится ближе к link1-->
    <link name="for_link2_1">
        <collision>
            <geometry>
                <box size="0.0425 0.002 0.035" />
            </geometry>
        </collision>
        <visual>
            <geometry>
                <box size="0.0425 0.002 0.035" />
            </geometry>
            <material name="light_grey" />
        </visual>
        
<inertial>
            <mass value="1e-05" />
            <inertia ixx="1.0" ixy="0.0" ixz="0.0" iyy="1.0" iyz="0.0" izz="1.0" />
        </inertial>

    </link>
    <!-- link1_to_for_link2_1 — фиксированное соединение -->
    <joint name="link1_to_for_link2_1" type="fixed">
        <parent link="link1" />
        <child link="for_link2_1" />
        <origin rpy="0 0 0" xyz="0.00125 -0.019 0.030000000000000002" />
    </joint>
    <!-- for_link2_2 — неподвижное звено, которое находится ближе к link2 -->
    <link name="for_link2_2">
        <collision>
            <geometry>
                <box size="0.06 0.002 0.04" />
            </geometry>
        </collision>
        <visual>
            <geometry>
                <box size="0.06 0.002 0.04" />
            </geometry>
            <material name="light_grey" />
        </visual>
        
<inertial>
            <mass value="1e-05" />
            <inertia ixx="1.0" ixy="0.0" ixz="0.0" iyy="1.0" iyz="0.0" izz="1.0" />
        </inertial>

    </link>
    <!-- for_link2_1_to_for_link2_2 — фиксированное соединение -->
    <joint name="for_link2_1_to_for_link2_2" type="fixed">
        <parent link="for_link2_1" />
        <child link="for_link2_2" />
        <origin rpy="0 0.7854 0" xyz="-0.028749999999999998 0 0.0175" />
    </joint>
    <!-- link2 — звено, которое осуществляет подъем/спуск конструкции ближе к основанию -->
    <link name="link2">
        <collision>
            <origin rpy="0 -0.9854 0" xyz="0.029500000000000002 0 0.046" />
            <geometry>
                <box size="0.14 0.002 0.04" />
            </geometry>
        </collision>
        <visual>
            <origin rpy="0 -0.9854 0" xyz="0.029500000000000002 0 0.046" />
            <geometry>
                <box size="0.14 0.002 0.04" />
            </geometry>
            <material name="light_grey" />
        </visual>
        
<inertial>
            <mass value="1e-05" />
            <inertia ixx="1.0" ixy="0.0" ixz="0.0" iyy="1.0" iyz="0.0" izz="1.0" />
        </inertial>

    </link>
    <!-- for_link2_to_link2 — подвижное соединение -->
    <joint name="for_link2_2_to_link2" type="revolute">
        <parent link="for_link2_2" />
        <child link="link2" />
        <origin rpy="0 0 0" xyz="-0.017 0.002 0.004" />
        <axis xyz="0 1 0" />
        <limit effort="0.245166" lower="-3.14" upper="0" velocity="3.15" />
        <dynamics damping="0.0" friction="0.0" />
    </joint>
    <!-- imu_block2 — внешняя часть imu-датчика, которая находится на link2 -->
    <link name="imu_block2">
        <collision>
            <origin rpy="0 0 0" xyz="0 0 0" />
            <geometry>
                <box size="0.015 0.025 0.005" />
            </geometry>
        </collision>
        <visual>
            <origin rpy="0 0 0" xyz="0 0 0" />
            <geometry>
                <box size="0.015 0.025 0.005" />
            </geometry>
            <material name="black" />
        </visual>
        
<inertial>
            <mass value="1e-05" />
            <inertia ixx="1.0" ixy="0.0" ixz="0.0" iyy="1.0" iyz="0.0" izz="1.0" />
        </inertial>

    </link>
    <!-- link2_to_imu_block2 — фиксированное соединение -->
    <joint name="link2_to_imu_block2" type="fixed">
        <parent link="link2" />
        <child link="imu_block2" />
        <origin rpy="0 5.2809090909 0" xyz="0 0.013500000000000002 0" />
    </joint>
    <!-- laser1 — внешняя часть лазерного дальномера, которая находится на link2 -->
    <link name="laser1">
        <collision>
            <origin rpy="0 0 0" xyz="0 0 0" />
            <geometry>
                <box size="0.001 0.005 0.002" />
            </geometry>
        </collision>
        <visual>
            <origin rpy="0 0 0" xyz="0 0 0" />
            <geometry>
                <box size="0.001 0.005 0.002" />
            </geometry>
            <material name="black" />
        </visual>
        
<inertial>
            <mass value="1e-05" />
            <inertia ixx="1.0" ixy="0.0" ixz="0.0" iyy="1.0" iyz="0.0" izz="1.0" />
        </inertial>

    </link>
    <!-- link2_to_laser1 — фиксированное соединение -->
    <joint name="link2_to_laser1" type="fixed">
        <parent link="link2" />
        <child link="laser1" />
        <origin rpy="0 3.7109090909 0" xyz="0.029500000000000002 0.018000000000000002 0.046" />
    </joint>
    <!-- link3 — звено, которое осуществляет подъем/спуск конструкции ближе к захвату -->
    <link name="link3">
        <collision>
            <origin rpy="0 0 0" xyz="0 0.019 0.015" />
            <geometry>
                <box size="0.06 0.04 0.045" />
            </geometry>
        </collision>
        <visual>
            <origin rpy="0 0 0" xyz="0 0.019 0.015" />
            <geometry>
                <box size="0.06 0.04 0.045" />
            </geometry>
            <material name="light_grey" />
        </visual>
        
<inertial>
            <mass value="1e-05" />
            <inertia ixx="1.0" ixy="0.0" ixz="0.0" iyy="1.0" iyz="0.0" izz="1.0" />
        </inertial>

    </link>
    <!-- link2_to_link3 — подвижное соединение -->
    <joint name="link2_to_link3" type="revolute">
        <parent link="link2" />
        <child link="link3" />
        <origin rpy="0 -0.7854 0" xyz="0.065 0 0.1" />
        <axis xyz="0 1 0" />
        <limit effort="0.245166" lower="0" upper="3.355" velocity="3.15" />
        <dynamics damping="0.0" friction="0.0" />
    </joint>
    <!-- imu_block3 — внешняя часть imu-датчика, которая находится на link3 -->
    <link name="imu_block3">
        <collision>
            <origin rpy="0 0 0" xyz="0 0 0" />
            <geometry>
                <box size="0.025 0.015 0.005" />
            </geometry>
        </collision>
        <visual>
            <origin rpy="0 0 0" xyz="0 0 0" />
            <geometry>
                <box size="0.025 0.015 0.005" />
            </geometry>
            <material name="black" />
        </visual>
        
<inertial>
            <mass value="1e-05" />
            <inertia ixx="1.0" ixy="0.0" ixz="0.0" iyy="1.0" iyz="0.0" izz="1.0" />
        </inertial>

    </link>
    <!-- link3_to_imu_block3 — фиксированное соединение -->
    <joint name="link3_to_imu_block3" type="fixed">
        <parent link="link3" />
        <child link="imu_block3" />
        <origin rpy="0 0 0" xyz="-0.0125 0.02 0.04" />
    </joint>
    <!-- link4 — звено, которое осуществляет поворот захвата влево/вправо -->
    <link name="link4">
        <collision>
            <origin rpy="0 -1.57 0" xyz="0 0 0" />
            <geometry>
                <cylinder length="0.1" radius="0.01" />
            </geometry>
        </collision>
        <visual>
            <origin rpy="0 -1.57 0" xyz="0 0 0" />
            <geometry>
                <cylinder length="0.1" radius="0.01" />
            </geometry>
            <material name="light_grey" />
        </visual>
        
<inertial>
            <mass value="1e-05" />
            <inertia ixx="1.0" ixy="0.0" ixz="0.0" iyy="1.0" iyz="0.0" izz="1.0" />
        </inertial>

    </link>
    <!-- link3_to_link4 — подвижное соединение -->
    <joint name="link3_to_link4" type="revolute">
        <parent link="link3" />
        <child link="link4" />
        <origin rpy="0 0 0" xyz="-0.08 0.02 0.02" />
        <axis xyz="1 0 0" />
        <limit effort="0.245166" lower="-1.57" upper="1.57" velocity="3.15" />
        <dynamics damping="0.0" friction="0.0" />
    </joint>
    <!-- for_link5_1 — неподвижное звено, которое находится рядом с link5 ближе к основанию -->
    <link name="for_link5_1">
        <collision>
            <geometry>
                <box size="0.0455 0.05 0.035" />
            </geometry>
        </collision>
        <visual>
            <geometry>
                <box size="0.0455 0.05 0.035" />
            </geometry>
            <material name="light_grey" />
        </visual>
        
<inertial>
            <mass value="1e-05" />
            <inertia ixx="1.0" ixy="0.0" ixz="0.0" iyy="1.0" iyz="0.0" izz="1.0" />
        </inertial>

    </link>
    <!-- link4_to_for_link5_1 — фиксированное соединение -->
    <joint name="link4_to_for_link5_1" type="fixed">
        <parent link="link4" />
        <child link="for_link5_1" />
        <origin rpy="0 0 0" xyz="-0.07275000000000001 0 0" />
    </joint>
    <!-- imu_block4 — внешняя часть imu-датчика, которая находится рядом с link5 ближе к основанию -->
    <link name="imu_block4">
        <collision>
            <origin rpy="0 0 0" xyz="0 0 0" />
            <geometry>
                <box size="0.015 0.025 0.005" />
            </geometry>
        </collision>
        <visual>
            <origin rpy="0 0 0" xyz="0 0 0" />
            <geometry>
                <box size="0.015 0.025 0.005" />
            </geometry>
            <material name="black" />
        </visual>
        
<inertial>
            <mass value="1e-05" />
            <inertia ixx="1.0" ixy="0.0" ixz="0.0" iyy="1.0" iyz="0.0" izz="1.0" />
        </inertial>

    </link>
    <!-- for_link5_1_to_imu_block4 — фиксированное соединение -->
    <joint name="for_link5_1_to_imu_block4" type="fixed">
        <parent link="for_link5_1" />
        <child link="imu_block4" />
        <origin rpy="0 0 0" xyz="0 0 0.02" />
    </joint>
    <!-- link5 —  звено, которое осуществляет движение захвата вверх/вниз -->
    <link name="link5">
        <collision>
            <origin rpy="0 0 0" xyz="-0.014875 0 0" />
            <geometry>
                <box size="0.02975 0.05 0.035" />
            </geometry>
        </collision>
        <visual>
            <origin rpy="0 0 0" xyz="-0.014875 0 0" />
            <geometry>
                <box size="0.02975 0.05 0.035" />
            </geometry>
            <material name="light_grey" />
        </visual>
        
<inertial>
            <mass value="1e-05" />
            <inertia ixx="1.0" ixy="0.0" ixz="0.0" iyy="1.0" iyz="0.0" izz="1.0" />
        </inertial>

    </link>
    <!-- for_link5_1_to_link5 — подвижное соединение -->
    <joint name="for_link5_1_to_link5" type="revolute">
        <parent link="for_link5_1" />
        <child link="link5" />
        <origin rpy="0 0 0" xyz="-0.02275 0 0" />
        <axis xyz="0 1 0" />
        <limit effort="0.245166" lower="-1.57" upper="1.57" velocity="3.15" />
        <dynamics damping="0.0" friction="0.0" />
    </joint>
    <!-- for_link5_2 — неподвижное звено, которое находится рядом с link5 ближе к захвату-->
    <link name="for_link5_2">
        <collision>
            <geometry>
                <box size="0.02975 0.05 0.035" />
            </geometry>
        </collision>
        <visual>
            <geometry>
                <box size="0.02975 0.05 0.035" />
            </geometry>
            <material name="light_grey" />
        </visual>
        
<inertial>
            <mass value="1e-05" />
            <inertia ixx="1.0" ixy="0.0" ixz="0.0" iyy="1.0" iyz="0.0" izz="1.0" />
        </inertial>

    </link>
    <!-- link5_to_for_link5_2 — фиксированное соединение -->
    <joint name="link5_to_for_link5_2" type="fixed">
        <parent link="link5" />
        <child link="for_link5_2" />
        <origin rpy="0 0 0" xyz="-0.044625 0 0" />
    </joint>
    <!-- imu_block5 — внешняя часть imu-датчика, которая находится рядом с link5 ближе к захвату -->
    <link name="imu_block5">
        <collision>
            <origin rpy="0 0 0" xyz="0 0 0" />
            <geometry>
                <box size="0.015 0.025 0.005" />
            </geometry>
        </collision>
        <visual>
            <origin rpy="0 0 0" xyz="0 0 0" />
            <geometry>
                <box size="0.015 0.025 0.005" />
            </geometry>
            <material name="black" />
        </visual>
        
<inertial>
            <mass value="1e-05" />
            <inertia ixx="1.0" ixy="0.0" ixz="0.0" iyy="1.0" iyz="0.0" izz="1.0" />
        </inertial>

    </link>
    <!-- for_link5_2_to_imu_block5 — фиксированное соединение -->
    <joint name="for_link5_2_to_imu_block5" type="fixed">
        <parent link="for_link5_2" />
        <child link="imu_block5" />
        <origin rpy="0 0 0" xyz="0 0 -0.02" />
    </joint>
    <!-- laser4 — внешняя часть лазерного дальномера, которая находится рядом с link5-->
    <link name="laser4">
        <collision>
            <geometry>
                <box size="0.001 0.005 0.002" />
            </geometry>
        </collision>
        <visual>
            <geometry>
                <box size="0.001 0.005 0.002" />
            </geometry>
            <material name="black" />
        </visual>
        
<inertial>
            <mass value="1e-05" />
            <inertia ixx="1.0" ixy="0.0" ixz="0.0" iyy="1.0" iyz="0.0" izz="1.0" />
        </inertial>

    </link>
    <!-- for_link5_2_to_laser4 — фиксированное соединение -->
    <joint name="for_link5_2_to_laser4" type="fixed">
        <parent link="for_link5_2" />
        <child link="laser4" />
        <origin rpy="0 3.14 0" xyz="-0.015375 0 0" />
    </joint>
    <!-- 
  ______________________ Захват_________________________ 
  -->
    <!-- right_finger — правый палец захвата -->
    <link name="right_finger">
        <visual>
            <origin rpy="0 0 0" xyz="-0.03 0 0" />
            <geometry>
                <box size="0.065 0.0075 0.002" />
            </geometry>
            <material name="light_grey" />
        </visual>
        
<inertial>
            <mass value="1e-05" />
            <inertia ixx="1.0" ixy="0.0" ixz="0.0" iyy="1.0" iyz="0.0" izz="1.0" />
        </inertial>

    </link>
    <!-- for_link5_2_to_right_finger — подвижное соединение -->
    <joint name="for_link5_2_to_right_finger" type="revolute">
        <parent link="for_link5_2" />
        <child link="right_finger" />
        <origin rpy="0 0 0" xyz="0 0.0075250000000000004 0.018500000000000003" />
        <axis xyz="0 0 1" />
        <limit effort="0.980665" lower="-1.57" upper="0" velocity="3.15" />
        <dynamics damping="0.0" friction="0.0" />
    </joint>
    <!-- right_tip — конец правого пальза захвата -->
    <link name="right_tip">
        <visual>
            <geometry>
                <box size="0.03 0.0075 0.004" />
            </geometry>
            <material name="light_grey" />
        </visual>
        
<inertial>
            <mass value="1e-05" />
            <inertia ixx="1.0" ixy="0.0" ixz="0.0" iyy="1.0" iyz="0.0" izz="1.0" />
        </inertial>

    </link>
    <!-- right_finger_to_right_tip — фиксированное соединение -->
    <joint name="right_finger_to_right_tip" type="fixed">
        <parent link="right_finger" />
        <child link="right_tip" />
        <origin rpy="0 0 0" xyz="-0.065 -0.00375 0.001" />
    </joint>
    <!-- left_finger — левый палец захвата -->
    <link name="left_finger">
        <visual>
            <origin rpy="0 0 0" xyz="-0.03 0 0" />
            <geometry>
                <box size="0.065 0.0075 0.002" />
            </geometry>
            <material name="light_grey" />
        </visual>
        
<inertial>
            <mass value="1e-05" />
            <inertia ixx="1.0" ixy="0.0" ixz="0.0" iyy="1.0" iyz="0.0" izz="1.0" />
        </inertial>

    </link>
    <!-- for_link5_2_to_left_finger — подвижное соединение -->
    <joint name="for_link5_2_to_left_finger" type="revolute">
        <parent link="for_link5_2" />
        <child link="left_finger" />
        <origin rpy="0 0 0" xyz="0 -0.0075250000000000004 0.018500000000000003" />
        <axis xyz="0 0 1" />
        <limit effort="0.980665" lower="0" upper="1.57" velocity="3.14" />
        <dynamics damping="0.0" friction="0.0" />
    </joint>
    <!-- left_tip — конец левого пальца захвата-->
    <link name="left_tip">
        <visual>
            <geometry>
                <box size="0.03 0.0075 0.004" />
            </geometry>
            <material name="light_grey" />
        </visual>
        
<inertial>
            <mass value="1e-05" />
            <inertia ixx="1.0" ixy="0.0" ixz="0.0" iyy="1.0" iyz="0.0" izz="1.0" />
        </inertial>

    </link>
    <!-- left_finger_to_left_tip — фиксированное соединение -->
    <joint name="left_finger_to_left_tip" type="fixed">
        <parent link="left_finger" />
        <child link="left_tip" />
        <origin rpy="0 0 0" xyz="-0.065 0.00375 0.001" />
    </joint>
    <!-- for_laser_right_1 — блок для laser3 ближе к right_finger-->
    <link name="for_laser_right_1">
        <collision>
            <geometry>
                <box size="0.0075 0.025 0.002" />
            </geometry>
        </collision>
        <visual>
            <geometry>
                <box size="0.0075 0.025 0.002" />
            </geometry>
            <material name="light_grey" />
        </visual>
        
<inertial>
            <mass value="1e-05" />
            <inertia ixx="1.0" ixy="0.0" ixz="0.0" iyy="1.0" iyz="0.0" izz="1.0" />
        </inertial>

    </link>
    <!-- right_finger_to_for_laser_right_1 — фиксированное соединение -->
    <joint name="right_finger_to_for_laser_right_1" type="fixed">
        <parent link="right_finger" />
        <child link="for_laser_right_1" />
        <origin rpy="0 0 0" xyz="-0.0325 0.005625 -0.002" />
    </joint>
    <!-- for_laser_right_2 — блок для laser3 дальше от right_finger -->
    <link name="for_laser_right_2">
        <collision>
            <geometry>
                <box size="0.065 0.002 0.01" />
            </geometry>
        </collision>
        <visual>
            <geometry>
                <box size="0.065 0.002 0.01" />
            </geometry>
            <material name="light_grey" />
        </visual>
        
<inertial>
            <mass value="1e-05" />
            <inertia ixx="1.0" ixy="0.0" ixz="0.0" iyy="1.0" iyz="0.0" izz="1.0" />
        </inertial>

    </link>
    <!-- for_laser_right_1_to_for_laser_right_2 — фиксированное соединение -->
    <joint name="for_laser_right_1_to_for_laser_right_2" type="fixed">
        <parent link="for_laser_right_1" />
        <child link="for_laser_right_2" />
        <origin rpy="0 0 0" xyz="-0.02875 0.0115 -0.006" />
    </joint>
    <!-- laser3 — внешняя часть лазерного дальномера, которая находится рядом с right_finger -->
    <link name="laser3">
        <collision>
            <geometry>
                <box size="0.001 0.005 0.002" />
            </geometry>
        </collision>
        <visual>
            <geometry>
                <box size="0.001 0.005 0.002" />
            </geometry>
            <material name="black" />
        </visual>
        
<inertial>
            <mass value="1e-05" />
            <inertia ixx="1.0" ixy="0.0" ixz="0.0" iyy="1.0" iyz="0.0" izz="1.0" />
        </inertial>

    </link>
    <!-- for_laser_right_2_to_laser3 — фиксированное соединение -->
    <joint name="for_laser_right_2_to_laser3" type="fixed">
        <parent link="for_laser_right_2" />
        <child link="laser3" />
        <origin rpy="0 0 -1.57" xyz="-0.01625 -0.0015 0" />
    </joint>
    <!-- for_laser_left_1 — блок для laser4 ближе к left_finger -->
    <link name="for_laser_left_1">
        <collision>
            <geometry>
                <box size="0.0075 0.025 0.002" />
            </geometry>
        </collision>
        <visual>
            <geometry>
                <box size="0.0075 0.025 0.002" />
            </geometry>
            <material name="light_grey" />
        </visual>
        
<inertial>
            <mass value="1e-05" />
            <inertia ixx="1.0" ixy="0.0" ixz="0.0" iyy="1.0" iyz="0.0" izz="1.0" />
        </inertial>

    </link>
    <!-- left_finger_to_for_laser_left_1 — фиксированное соединение -->
    <joint name="left_finger_to_for_laser_left_1" type="fixed">
        <parent link="left_finger" />
        <child link="for_laser_left_1" />
        <origin rpy="0 0 0" xyz="-0.0325 -0.005625 -0.002" />
    </joint>
    <!-- for_laser_left_2 — блок для laser4 дальше от left_finger-->
    <link name="for_laser_left_2">
        <collision>
            <geometry>
                <box size="0.065 0.002 0.01" />
            </geometry>
        </collision>
        <visual>
            <geometry>
                <box size="0.065 0.002 0.01" />
            </geometry>
            <material name="light_grey" />
        </visual>
        
<inertial>
            <mass value="1e-05" />
            <inertia ixx="1.0" ixy="0.0" ixz="0.0" iyy="1.0" iyz="0.0" izz="1.0" />
        </inertial>

    </link>
    <!-- for_laser_left_1_to_for_laser_left_2 — фиксированное соединение -->
    <joint name="for_laser_left_1_to_for_laser_left_2" type="fixed">
        <parent link="for_laser_left_1" />
        <child link="for_laser_left_2" />
        <origin rpy="0 0 0" xyz="-0.02875 -0.0115 -0.006" />
    </joint>
    <!-- laser2 — внешняя часть лазерного дальномера, которая находится рядом с left_finger -->
    <link name="laser2">
        <collision>
            <geometry>
                <box size="0.001 0.005 0.002" />
            </geometry>
        </collision>
        <visual>
            <geometry>
                <box size="0.001 0.005 0.002" />
            </geometry>
            <material name="black" />
        </visual>
        
<inertial>
            <mass value="1e-05" />
            <inertia ixx="1.0" ixy="0.0" ixz="0.0" iyy="1.0" iyz="0.0" izz="1.0" />
        </inertial>

    </link>
    <!-- for_laser_left_2_to_laser2 — фиксированное соединение -->
    <joint name="for_laser_left_2_to_laser2" type="fixed">
        <parent link="for_laser_left_2" />
        <child link="laser2" />
        <origin rpy="0 0 1.57" xyz="-0.01625 0.0015 0" />
    </joint>
    <!--
  ____________________________Датчики____________________________
   -->
    <!-- laser1 — лазерный дальномер, который находится на link2 -->
    <gazebo reference="laser1">
        <sensor name="laser1" type="ray">
            <pose>0 0 0 0 0 0</pose>
            <visualize>true</visualize>
            <update_rate>10</update_rate>
            <ray>
                <scan>
                    <horizontal>
                        <samples>1</samples>
                        <resolution>1</resolution>
                        <min_angle>0.0</min_angle>
                        <max_angle>0.0</max_angle>
                    </horizontal>
                </scan>
                <range>
                    <min>0.001</min>
                    <max>2.0</max>
                    <resolution>0.01</resolution>
                </range>
            </ray>
            <plugin filename="libgazebo_ros_laser.so" name="gazebo_ros_head_hokuyo_controller">
                <topicName>laser1/scan</topicName>
                <frameName>laser1</frameName>
            </plugin>
        </sensor>
    </gazebo>
    <!-- laser3 — лазерный дальномер, который находится рядом с right_finger -->
    <gazebo reference="laser3">
        <sensor name="laser3" type="ray">
            <pose>0 0 0 0 0 0</pose>
            <visualize>true</visualize>
            <update_rate>10</update_rate>
            <ray>
                <scan>
                    <horizontal>
                        <samples>1</samples>
                        <resolution>1</resolution>
                        <min_angle>0.0</min_angle>
                        <max_angle>0.0</max_angle>
                    </horizontal>
                </scan>
                <range>
                    <min>0.001</min>
                    <max>2.0</max>
                    <resolution>0.01</resolution>
                </range>
            </ray>
            <plugin filename="libgazebo_ros_laser.so" name="gazebo_ros_head_hokuyo_controller">
                <topicName>laser3/scan</topicName>
                <frameName>laser3</frameName>
            </plugin>
        </sensor>
    </gazebo>
    <!-- laser2 — лазерный дальномер, который находится рядом с left_finger -->
    <gazebo reference="laser2">
        <sensor name="laser2" type="ray">
            <pose>0 0 0 0 0 0</pose>
            <visualize>true</visualize>
            <update_rate>10</update_rate>
            <ray>
                <scan>
                    <horizontal>
                        <samples>1</samples>
                        <resolution>1</resolution>
                        <min_angle>0.0</min_angle>
                        <max_angle>0.0</max_angle>
                    </horizontal>
                </scan>
                <range>
                    <min>0.001</min>
                    <max>2.0</max>
                    <resolution>0.01</resolution>
                </range>
            </ray>
            <plugin filename="libgazebo_ros_laser.so" name="gazebo_ros_head_hokuyo_controller">
                <topicName>laser2/scan</topicName>
                <frameName>laser2</frameName>
            </plugin>
        </sensor>
    </gazebo>
    <!-- laser4 — лазерный дальномер, который находится рядом с link5 -->
    <gazebo reference="laser4">
        <sensor name="laser4" type="ray">
            <pose>0 0 0 0 0 -1.57</pose>
            <visualize>true</visualize>
            <update_rate>10</update_rate>
            <ray>
                <scan>
                    <horizontal>
                        <samples>1</samples>
                        <resolution>1</resolution>
                        <min_angle>0.0</min_angle>
                        <max_angle>0.0</max_angle>
                    </horizontal>
                </scan>
                <range>
                    <min>0.001</min>
                    <max>2.0</max>
                    <resolution>0.01</resolution>
                </range>
            </ray>
            <plugin filename="libgazebo_ros_laser.so" name="gazebo_ros_head_hokuyo_controller">
                <topicName>laser4/scan</topicName>
                <frameName>laser4</frameName>
            </plugin>
        </sensor>
    </gazebo>
    <!-- imu1 — imu-датчик, который находится рядом с link1-->
    <gazebo>
        <plugin filename="libgazebo_ros_imu.so" name="imu_plugin">
            <topicName>imu1/data</topicName>
            <serviceName>imu1/service</serviceName>
            <bodyName>imu_block1</bodyName>
            <frameName>imu_block1</frameName>
            <rpyOffsets>0 0 0</rpyOffsets>
            <updateRate>10.0</updateRate>
            <alwaysOn>true</alwaysOn>
        </plugin>
    </gazebo>
    <!-- imu2 — imu-датчик, который находится на link2 -->
    <gazebo>
        <plugin filename="libgazebo_ros_imu.so" name="imu_plugin">
            <topicName>imu2/data</topicName>
            <serviceName>imu2/service</serviceName>
            <bodyName>imu_block2</bodyName>
            <frameName>imu_block2</frameName>
            <rpyOffsets>0 0 0</rpyOffsets>
            <updateRate>10.0</updateRate>
            <alwaysOn>true</alwaysOn>
        </plugin>
    </gazebo>
    <!-- imu3 — imu-датчик, который находится на link3-->
    <gazebo>
        <plugin filename="libgazebo_ros_imu.so" name="imu_plugin">
            <topicName>imu3/data</topicName>
            <serviceName>imu3/service</serviceName>
            <bodyName>imu_block3</bodyName>
            <frameName>imu_block3</frameName>
            <rpyOffsets>0 0 0</rpyOffsets>
            <updateRate>10.0</updateRate>
            <alwaysOn>true</alwaysOn>
        </plugin>
    </gazebo>
    <!-- imu4 — imu-датчик, который находится рядом с link5 ближе к основанию-->
    <gazebo>
        <plugin filename="libgazebo_ros_imu.so" name="imu_plugin">
            <topicName>imu4/data</topicName>
            <serviceName>imu4/service</serviceName>
            <bodyName>imu_block4</bodyName>
            <frameName>imu_block4</frameName>
            <rpyOffsets>0 0 0</rpyOffsets>
            <updateRate>10.0</updateRate>
            <alwaysOn>true</alwaysOn>
        </plugin>
    </gazebo>
    <!-- imu5 — imu-датчик, который находится рядом с link5 ближе к захвату-->
    <gazebo>
        <plugin filename="libgazebo_ros_imu.so" name="imu_plugin">
            <topicName>imu5/data</topicName>
            <serviceName>imu5/service</serviceName>
            <bodyName>imu_block5</bodyName>
            <frameName>imu_block5</frameName>
            <rpyOffsets>0 0 0</rpyOffsets>
            <updateRate>10.0</updateRate>
            <alwaysOn>true</alwaysOn>
        </plugin>
    </gazebo>
    <!-- подключение цветов gazebo -->
    <gazebo reference="imu1">
        <material>Gazebo/Black</material>
    </gazebo>
    <gazebo reference="imu2">
        <material>Gazebo/Black</material>
    </gazebo>
    <gazebo reference="imu3">
        <material>Gazebo/Black</material>
    </gazebo>
    <gazebo reference="imu4">
        <material>Gazebo/Black</material>
    </gazebo>
    <gazebo reference="imu5">
        <material>Gazebo/Black</material>
    </gazebo>
    <gazebo reference="laser1">
        <material>Gazebo/Black</material>
    </gazebo>
    <gazebo reference="laser2">
        <material>Gazebo/Black</material>
    </gazebo>
    <gazebo reference="laser3">
        <material>Gazebo/Black</material>
    </gazebo>
    <gazebo reference="laser4">
        <material>Gazebo/Black</material>
    </gazebo>
    
<transmission name="trans_base2_to_link1">
        <type>transmission_interface/SimpleTransmission</type>
        <joint name="base2_to_link1">
            <hardwareInterface>hardware_interface/PositionJointInterface</hardwareInterface>
        </joint>
        <actuator name="base2_to_link1_motor">
            <hardwareInterface>hardware_interface/PositionJointInterface</hardwareInterface>
            <mechanicalReduction>1</mechanicalReduction>
        </actuator>
    </transmission>
    <transmission name="trans_for_link2_2_to_link2">
        <type>transmission_interface/SimpleTransmission</type>
        <joint name="for_link2_2_to_link2">
            <hardwareInterface>hardware_interface/PositionJointInterface</hardwareInterface>
        </joint>
        <actuator name="for_link2_2_to_link2_motor">
            <hardwareInterface>hardware_interface/PositionJointInterface</hardwareInterface>
            <mechanicalReduction>1</mechanicalReduction>
        </actuator>
    </transmission>
    <transmission name="trans_link2_to_link3">
        <type>transmission_interface/SimpleTransmission</type>
        <joint name="link2_to_link3">
            <hardwareInterface>hardware_interface/PositionJointInterface</hardwareInterface>
        </joint>
        <actuator name="link2_to_link3_motor">
            <hardwareInterface>hardware_interface/PositionJointInterface</hardwareInterface>
            <mechanicalReduction>1</mechanicalReduction>
        </actuator>
    </transmission>
    <transmission name="trans_link3_to_link4">
        <type>transmission_interface/SimpleTransmission</type>
        <joint name="link3_to_link4">
            <hardwareInterface>hardware_interface/PositionJointInterface</hardwareInterface>
        </joint>
        <actuator name="link3_to_link4_motor">
            <hardwareInterface>hardware_interface/PositionJointInterface</hardwareInterface>
            <mechanicalReduction>1</mechanicalReduction>
        </actuator>
    </transmission>
    <transmission name="trans_for_link5_1_to_link5">
        <type>transmission_interface/SimpleTransmission</type>
        <joint name="for_link5_1_to_link5">
            <hardwareInterface>hardware_interface/PositionJointInterface</hardwareInterface>
        </joint>
        <actuator name="for_link5_1_to_link5_motor">
            <hardwareInterface>hardware_interface/PositionJointInterface</hardwareInterface>
            <mechanicalReduction>1</mechanicalReduction>
        </actuator>
    </transmission>
    <transmission name="trans_for_link5_2_to_right_finger">
        <type>transmission_interface/SimpleTransmission</type>
        <joint name="for_link5_2_to_right_finger">
            <hardwareInterface>hardware_interface/PositionJointInterface</hardwareInterface>
        </joint>
        <actuator name="for_link5_2_to_right_finger_motor">
            <hardwareInterface>hardware_interface/PositionJointInterface</hardwareInterface>
            <mechanicalReduction>1</mechanicalReduction>
        </actuator>
    </transmission>
    <transmission name="trans_for_link5_2_to_left_finger">
        <type>transmission_interface/SimpleTransmission</type>
        <joint name="for_link5_2_to_left_finger">
            <hardwareInterface>hardware_interface/PositionJointInterface</hardwareInterface>
        </joint>
        <actuator name="for_link5_2_to_left_finger_motor">
            <hardwareInterface>hardware_interface/PositionJointInterface</hardwareInterface>
            <mechanicalReduction>1</mechanicalReduction>
        </actuator>
    </transmission>
    <gazebo>
        <plugin name="gazebo_ros_control" filename="libgazebo_ros_control.so">
            <robotNamespace>/</robotNamespace>
        </plugin>
    </gazebo>
</robot>
